<?xml version="1.0" encoding="UTF-8"?>
<!-- =================================================================================== -->
<!--                   TO, https://juansantacoloma.github.io/                            -->
<!-- =================================================================================== -->
<!-- This file contains the description of the To robot. -->
<!-- xmlns:xacro="http://www.ros.org/wiki/xacro" -->
<robot  name="to">
   <!-- Material for the visual primitives -->
   <!-- <material name="to_material">
      <color rgba="1 0.0 0.0 0.5" />
   </material> -->
   
   <!-- Base link -->
   <link name="base">
      <visual>
         <origin rpy="0 0 0" xyz="0 0 0" />
         <geometry>
            <!-- <mesh filename="package://to_description/meshes/chasis_abs.stl" scale="0.001 0.001     0.001" /> -->
            <mesh filename="package://to_description/meshes/chasis_abs_simply3.dae" scale="0.001 0.001 0.001" />
         </geometry>
         <!-- <material name="to_material" /> -->
      </visual>
      <collision>
         <!-- Main Body -->
         <origin rpy="0 0 0" xyz="0 0 0.0" />
         <geometry>
            <box size="0.600 0.255 0.01" />
         </geometry>
      </collision>
   </link>
   
   <!-- Dummy inertia link, because KDL cannot have inertia on the base link -->
   <link name="base_inertia">
      <inertial>
         <!-- <origin rpy="0 0 0" xyz="0.005 0.0 0.004" /> -->
         <mass value="0.293" />
         <inertia ixx="0.002" ixy="-0.000" ixz="-0.00" iyy="0.01" iyz="-0.00" izz="0.012" />
      </inertial>
   </link>
   <!-- fixed -->
   <joint name="base_to_base_inertia" type="fixed">
      <origin xyz="0 0 0" rpy="0 0 0"/>
      <parent link="base" />
      <child link="base_inertia" />
   </joint>
   <!-- ****************************** Pata frente izquierda ***************** -->
   <!-- Link AB Left -->
   <link name="LF_HIP">
      <visual>
         <origin rpy="0 0 0.0" xyz="0 0 0" />
         <geometry>
            <!-- <mesh filename="package://to_description/meshes/ab_lf.stl" scale="0.001 0.001     0.001" /> -->
            <mesh filename="package://to_description/meshes/ab_lf.dae" scale="0.001 0.001     0.001" />
         </geometry>
         <!-- <material name="to_material" /> -->
      </visual>
      <collision>
          <!-- Main Body -->
         <origin rpy="0 0 0" xyz="0.143 0 0.0" />
         <geometry>
            <box size="0.181912 0.061 0.060" />
         </geometry>
      </collision>
      <inertial>
         <origin rpy="0 0 0" xyz="0.128996 -0.003375 0.00016" />
         <mass value="0.272" />
         <inertia ixx="0.000" ixy="-0.000" ixz="0.000" iyy="0.001" iyz="0.000" izz="0.001" />
      </inertial>
   </link>
  <!-- Abduction joint  -->
   <joint name="LF_ABD" type="revolute">
      <parent link="base" />
      <child link="LF_HIP" />
      <origin xyz="0.055657 0.105030 0.042319" rpy="0.0 0.0 0.0"/>
      <axis xyz="1 0 0" />
      <limit command_effort="40" current="10" effort="80" gear_velocity="10" lower="-0.42" upper="1.14" velocity="15" />
      <dynamics damping="0.0" friction="0.0" />
   </joint>
   <!-- Link flex_1 Left -->
   <link name="LF_FLX1">
      <visual>
         <origin rpy="0 0 0.0" xyz="0 0 0" />
         <geometry>
            <!-- <mesh filename="package://to_description/meshes/flex_1_fl.stl" scale="0.001 0.001     0.001" /> -->
            <mesh filename="package://to_description/meshes/flex_1_fl.dae" scale="0.001 0.001     0.001" />
         </geometry>
         <!-- <material name="to_material" /> -->
      </visual>
      <collision>
          <!-- Main Body -->
         <origin rpy="0 0 0" xyz="0.0 0.04985 -0.0875" />
         <geometry>
            <box size="0.061 0.060 0.181912" />
         </geometry>
      </collision>
      <inertial>
         <origin rpy="0 0 0" xyz="-0.0013 0.045121 -0.075788" />
         <mass value="0.263" />
         <inertia ixx="0.001" ixy="-0.000" ixz="0.000" iyy="0.001" iyz="0.000" izz="0.001" />
      </inertial>
   </link>
  <!-- Flexion  joint 1  -->
   <joint name="LF_HF1" type="revolute">
      <parent link="LF_HIP" />
      <child link="LF_FLX1" />
      <origin xyz="0.204912 0.014725 0.0" rpy="0.0 0.0 0.0"/>
      <axis xyz="0 1 0" />
      <limit command_effort="40" current="10" effort="80" gear_velocity="10" lower="-1.62" upper="1.62" velocity="15" />
      <dynamics damping="0.0" friction="0.0" />
   </joint>
   <!-- Link flex_2 Left -->
   <link name="LF_FLX2">
      <visual>
         <origin rpy="0 0 0.0" xyz="0 0 0" />
         <geometry>
            <!-- <mesh filename="package://to_description/meshes/tibia_left.stl" scale="0.001 0.001     0.001" /> -->
            <mesh filename="package://to_description/meshes/tibia.dae" scale="0.001 0.001     0.001" />
         </geometry>
         <!-- <material name="to_material" /> -->
      </visual>
      <collision>
          <!-- Main Body -->
         <origin rpy="0 0 0" xyz="0.0 0.0305 -0.063" />
         <geometry>
            <box size="0.021 0.021 0.146" />
         </geometry>
      </collision>
      <inertial>
         <origin rpy="0 0 0" xyz="-0.0013 0.045121 -0.075788" />
         <mass value="0.263" />
         <inertia ixx="0.001" ixy="-0.000" ixz="0.000" iyy="0.001" iyz="0.000" izz="0.001" />
      </inertial>
   </link>
  <!-- Flex  joint 2  -->
   <joint name="LF_FF2" type="revolute">
      <parent link="LF_FLX1" />
      <child link="LF_FLX2" />
      <origin xyz="0.0 0.064575 -0.1534" rpy="0.0 0.0 0.0"/>
      <axis xyz="0 1 0" />
      <limit command_effort="40" current="10" effort="80" gear_velocity="10" lower="-1.62" upper="1.62" velocity="15" />
      <dynamics damping="0.0" friction="0.0" />
   </joint>
   <!-- foot -->
   <link name="LF_FT">
      <visual>
         <origin rpy="0 0 0.0" xyz="0 0 0" />
         <geometry>
            <!-- <mesh filename="package://to_description/meshes/foot.stl" scale="0.001 0.001     0.001" /> -->
            <mesh filename="package://to_description/meshes/foot.dae" scale="0.001 0.001     0.001" />
         </geometry>
         <!-- <material name="to_material" /> -->
      </visual>
      <collision>
         <origin xyz="0 0.0 0.0278" />
         <geometry>
            <sphere radius="0.0278" />
         </geometry>
      </collision>
      <inertial>
         <origin rpy="0 0 0" xyz="-0.0013 0.045121 -0.075788" />
         <mass value="0.263" />
         <inertia ixx="0.001" ixy="-0.000" ixz="0.000" iyy="0.001" iyz="0.000" izz="0.001" />
      </inertial>
   </link>
   <!-- fixed -->
   <joint name="LF_FT_FX" type="fixed">
      <parent link="LF_FLX2" />
      <child link="LF_FT" />
      <origin xyz="0.0 0.0304 -0.192206" rpy="0 0 0"/>
   </joint>
   <!-- ****************************** Pata frente derecha ***************** -->
   <!-- Link AB rigth front -->
   <link name="RF_HIP">
      <visual>
         <origin rpy="0 0 0.0" xyz="0 0 0" />
         <geometry>
            <!-- <mesh filename="package://to_description/meshes/ab_fr.stl" scale="0.001 0.001     0.001" /> -->
            <mesh filename="package://to_description/meshes/ab_fr_simplify.dae" scale="0.001 0.001     0.001" />
         </geometry>
         <!-- <material name="to_material" /> -->
      </visual>
      <collision>
          <!-- Main Body -->
         <origin rpy="0 0 0" xyz="0.090961 0 0.0" />
         <geometry>
            <box size="0.181912 0.061 0.060" />
         </geometry>
      </collision>
      <inertial>
         <origin rpy="0 0 0" xyz="0.087 -0.004 0.000" />
         <mass value="0.255" />
         <inertia ixx="0.000" ixy="-0.000" ixz="0.000" iyy="0.001" iyz="0.000" izz="0.001" />
      </inertial>
   </link>
  <!-- Abduction joint  -->
   <joint name="RF_ABD" type="revolute">
      <parent link="base" />
      <child link="RF_HIP" />
      
      <origin xyz="0.102751 -0.105030 0.041319" rpy="0.0 0.0 0.0"/>
      <axis xyz="1 0 0" />
      <limit command_effort="40" current="10" effort="80" gear_velocity="10" lower="-0.42" upper="1.14" velocity="15" />
      <dynamics damping="0.0" friction="0.0" />
   </joint>
   <!-- Link flex_1 Rigth -->
   <link name="RF_FLX1">
      <visual>
         <origin rpy="0 0 0.0" xyz="0 0 0" />
         <geometry>
            <!-- <mesh filename="package://to_description/meshes/flex_1_fr.stl" scale="0.001 0.001     0.001" /> -->
            <mesh filename="package://to_description/meshes/flex_1_fr.dae" scale="0.001 0.001     0.001" />
         </geometry>
         <!-- <material name="to_material" /> -->
      </visual>
      <collision>
          <!-- Main Body -->
         <origin rpy="0 0 0" xyz="0.0 -0.04985 -0.0875" />
         <geometry>
            <box size="0.061 0.060 0.181912" />
         </geometry>
      </collision>
      <inertial>
         <origin rpy="0 0 0" xyz="0.000 -0.045121 -0.075788" />
         <mass value="0.263" />
         <inertia ixx="0.001" ixy="-0.000" ixz="0.000" iyy="0.001" iyz="0.000" izz="0.001" />
      </inertial>
   </link>
  <!-- Flexion  joint 1  -->
   <joint name="RF_HF1" type="revolute">
      <parent link="RF_HIP" />
      <child link="RF_FLX1" />
      <origin xyz="0.157912 -0.014725 0.0" rpy="0.0 0.0 0.0"/>
      <axis xyz="0 1 0" />
      <limit command_effort="40" current="10" effort="80" gear_velocity="10" lower="-1.62" upper="1.62" velocity="15" />
      <dynamics damping="0.0" friction="0.0" />
   </joint>
   <!-- Link flex_2 rigth front -->
   <link name="RF_FLX2">
      <visual>
         <origin rpy="0 0 0.0" xyz="0 0 0" />
         <geometry>
            <!-- <mesh filename="package://to_description/meshes/tibia_rigth.stl" scale="0.001 0.001     0.001" /> -->
            <mesh filename="package://to_description/meshes/tibia_rigth.dae" scale="0.001 0.001     0.001" />
         </geometry>
         <!-- <material name="to_material" /> -->
      </visual>
      <collision>
          <!-- Main Body -->
         <origin rpy="0 0 0" xyz="0.0 -0.0305 -0.063" />
         <geometry>
            <box size="0.021 0.021 0.146" />
         </geometry>
      </collision>
      <inertial>
         <origin rpy="0 0 0" xyz="-0.0013 0.045121 -0.075788" />
         <mass value="0.263" />
         <inertia ixx="0.001" ixy="-0.000" ixz="0.000" iyy="0.001" iyz="0.000" izz="0.001" />
      </inertial>
   </link>
  <!-- Flex  joint 2  -->
   <joint name="RF_FF2" type="revolute">
      <parent link="RF_FLX1" />
      <child link="RF_FLX2" />
      <origin xyz="0.0 -0.064575 -0.1534" rpy="0.0 0.0 0.0"/>
      <axis xyz="0 1 0" />
      <limit command_effort="40" current="10" effort="80" gear_velocity="10" lower="-1.62" upper="1.62" velocity="15" />
      <dynamics damping="0.0" friction="0.0" />
   </joint>
   <!-- foot -->
   <link name="RF_FT">
      <visual>
         <origin rpy="0 0 0.0" xyz="0 0 0" />
         <geometry>
            <!-- <mesh filename="package://to_description/meshes/foot.stl" scale="0.001 0.001     0.001" /> -->
            <mesh filename="package://to_description/meshes/foot.dae" scale="0.001 0.001     0.001" />
         </geometry>
         <!-- <material name="to_material" /> -->
      </visual>
      <collision>
         <origin xyz="0 0.0 0.0278" />
         <geometry>
            <sphere radius="0.0278" />
         </geometry>
      </collision>
      <inertial>
         <origin rpy="0 0 0" xyz="-0.0013 0.045121 -0.075788" />
         <mass value="0.263" />
         <inertia ixx="0.001" ixy="-0.000" ixz="0.000" iyy="0.001" iyz="0.000" izz="0.001" />
      </inertial>
   </link>
   <!-- fixed -->
   <joint name="RF_FT_FX" type="fixed">
      <parent link="RF_FLX2" />
      <child link="RF_FT" />
      <origin xyz="0.0 -0.0304 -0.192206" rpy="0 0 0"/>
   </joint>
   <!-- ****************************** Pata trasera izquierda ***************** -->
   <!-- Link AB left rear -->
   <link name="LR_HIP">
      <visual>
         <origin rpy="0 0 0.0" xyz="0 0 0" />
         <geometry>
            <!-- <mesh filename="package://to_description/meshes/ab_left_rear.stl" scale="0.001 0.001     0.001" /> -->
            <mesh filename="package://to_description/meshes/ab_left_rear.dae" scale="0.001 0.001     0.001" />
         </geometry>
         <!-- <material name="to_material" /> -->
      </visual>
      <collision>
          <!-- Main Body -->
         <origin rpy="0 0 0" xyz="-0.090961 0 0.0" />
         <geometry>
            <box size="0.181912 0.061 0.060" />
         </geometry>
      </collision>
      <inertial>
         <origin rpy="0 0 0" xyz="0.087 -0.004 0.000" />
         <mass value="0.255" />
         <inertia ixx="0.000" ixy="-0.000" ixz="0.000" iyy="0.001" iyz="0.000" izz="0.001" />
      </inertial>
   </link>
  <!-- Abduction joint  -->
   <joint name="LR_ABD" type="revolute">
      <parent link="base" />
      <child link="LR_HIP" />
      <origin xyz="-0.102751 0.105030 0.041319" rpy="0.0 0.0 0.0"/>
      <axis xyz="1 0 0" />
      <limit command_effort="40" current="10" effort="80" gear_velocity="10" lower="-0.42" upper="1.14" velocity="15" />
      <dynamics damping="0.0" friction="0.0" />
   </joint>
   <!-- Link flex_1 Left rigth -->
   <link name="LR_FLX1">
      <visual>
         <origin rpy="0 0 0.0" xyz="0 0 0" />
         <geometry>
            <!-- <mesh filename="package://to_description/meshes/flex_1_fl.stl" scale="0.001 0.001     0.001" /> -->
            <mesh filename="package://to_description/meshes/flex_1_fl.dae" scale="0.001 0.001     0.001" />
         </geometry>
         <!-- <material name="to_material" /> -->
      </visual>
      <collision>
          <!-- Main Body -->
         <origin rpy="0 0 0" xyz="0.0 0.04985 -0.0875" />
         <geometry>
            <box size="0.061 0.060 0.181912" />
         </geometry>
      </collision>
      <inertial>
         <origin rpy="0 0 0" xyz="-0.0013 0.045121 -0.075788" />
         <mass value="0.263" />
         <inertia ixx="0.001" ixy="-0.000" ixz="0.000" iyy="0.001" iyz="0.000" izz="0.001" />
      </inertial>
   </link>
  <!-- Flexion  joint 1  -->
   <joint name="LR_HF1" type="revolute">
      <parent link="LR_HIP" />
      <child link="LR_FLX1" />
      <origin xyz="-0.157912 0.014725 0.0" rpy="0.0 0.0 0.0"/>
      <axis xyz="0 1 0" />
      <limit command_effort="40" current="10" effort="80" gear_velocity="10" lower="-1.62" upper="1.62" velocity="15" />
      <dynamics damping="0.0" friction="0.0" />
   </joint>
   <!-- Link flex_2 Left -->
   <link name="LR_FLX2">
      <visual>
         <origin rpy="0 0 0.0" xyz="0 0 0" />
         <geometry>
            <!-- <mesh filename="package://to_description/meshes/tibia_left.stl" scale="0.001 0.001     0.001" /> -->
            <mesh filename="package://to_description/meshes/tibia.dae" scale="0.001 0.001     0.001" />
         </geometry>
         <!-- <material name="to_material" /> -->
      </visual>
      <collision>
          <!-- Main Body -->
         <origin rpy="0 0 0" xyz="0.0 0.0305 -0.063" />
         <geometry>
            <box size="0.021 0.021 0.146" />
         </geometry>
      </collision>
      <inertial>
         <origin rpy="0 0 0" xyz="-0.0013 0.045121 -0.075788" />
         <mass value="0.263" />
         <inertia ixx="0.001" ixy="-0.000" ixz="0.000" iyy="0.001" iyz="0.000" izz="0.001" />
      </inertial>
   </link>
  <!-- Flex  joint 2  -->
   <joint name="LR_FF2" type="revolute">
      <parent link="LR_FLX1" />
      <child link="LR_FLX2" />
      <origin xyz="0.0 0.064575 -0.1534" rpy="0.0 0.0 0.0"/>
      <axis xyz="0 1 0" />
      <limit command_effort="40" current="10" effort="80" gear_velocity="10" lower="-1.62" upper="1.62" velocity="15" />
      <dynamics damping="0.0" friction="0.0" />
   </joint>
   <!-- foot -->
   <link name="LR_FT">
      <visual>
         <origin rpy="0 0 0.0" xyz="0 0 0" />
         <geometry>
            <!-- <mesh filename="package://to_description/meshes/foot.stl" scale="0.001 0.001     0.001" /> -->
            <mesh filename="package://to_description/meshes/foot.dae" scale="0.001 0.001     0.001" />
         </geometry>
         <!-- <material name="to_material" /> -->
      </visual>
      <collision>
         <origin xyz="0 0.0 0.0278" />
         <geometry>
            <sphere radius="0.0278" />
         </geometry>
      </collision>
      <inertial>
         <origin rpy="0 0 0" xyz="-0.0013 0.045121 -0.075788" />
         <mass value="0.263" />
         <inertia ixx="0.001" ixy="-0.000" ixz="0.000" iyy="0.001" iyz="0.000" izz="0.001" />
      </inertial>
   </link>
   <!-- fixed -->
   <joint name="LR_FT_FX" type="fixed">
      <parent link="LR_FLX2" />
      <child link="LR_FT" />
      <origin xyz="0.0 0.0304 -0.192206" rpy="0 0 0"/>
   </joint>
   <!-- ****************************** Pata trasera derecha ***************** -->
   <!-- Link AB rigth rear -->
   <link name="RR_HIP">
      <visual>
         <origin rpy="0 0 0.0" xyz="0 0 0" />
         <geometry>
            <!-- <mesh filename="package://to_description/meshes/ab_rrear.stl" scale="0.001 0.001     0.001" /> -->
            <mesh filename="package://to_description/meshes/ab_rrear.dae" scale="0.001 0.001     0.001" />
         </geometry>
         <!-- <material name="to_material" /> -->
      </visual>
      <collision>
          <!-- Main Body -->
         <origin rpy="0 0 0" xyz="-0.143 0 0.0" />
         <geometry>
            <box size="0.181912 0.061 0.060" />
         </geometry>
      </collision>
      <inertial>
         <origin rpy="0 0 0" xyz="-0.087 -0.004 0.000" />
         <mass value="0.255" />
         <inertia ixx="0.000" ixy="-0.000" ixz="0.000" iyy="0.001" iyz="0.000" izz="0.001" />
      </inertial>
   </link>
  <!-- Abduction joint  -->
   <joint name="RR_ABD" type="revolute">
      <parent link="base" />
      <child link="RR_HIP" />
      <origin xyz="-0.055657 -0.105030 0.041319" rpy="0.0 0.0 0.0"/>
      <axis xyz="1 0 0" />
      <limit command_effort="40" current="10" effort="80" gear_velocity="10" lower="-0.42" upper="1.14" velocity="15" />
      <dynamics damping="0.0" friction="0.0" />
   </joint>
   <!-- Link flex_1 Rigth -->
   <link name="RR_FLX1">
      <visual>
         <origin rpy="0 0 0.0" xyz="0 0 0" />
         <geometry>
            <!-- <mesh filename="package://to_description/meshes/flex_1_fr.stl" scale="0.001 0.001     0.001" /> -->
            <mesh filename="package://to_description/meshes/flex_1_fr.dae" scale="0.001 0.001     0.001" />
         </geometry>
         <!-- <material name="to_material" /> -->
      </visual>
      <collision>
          <!-- Main Body -->
         <origin rpy="0 0 0" xyz="0.0 -0.04985 -0.0875" />
         <geometry>
            <box size="0.061 0.060 0.181912" />
         </geometry>
      </collision>
      <inertial>
         <origin rpy="0 0 0" xyz="0.000 -0.045121 -0.075788" />
         <mass value="0.263" />
         <inertia ixx="0.001" ixy="-0.000" ixz="0.000" iyy="0.001" iyz="0.000" izz="0.001" />
      </inertial>
   </link>
  <!-- Flexion  joint 1  -->
   <joint name="RR_HF1" type="revolute">
      <parent link="RR_HIP" />
      <child link="RR_FLX1" />
      <origin xyz="-0.204912 -0.014725 0.0" rpy="0.0 0.0 0.0"/>
      <axis xyz="0 1 0" />
      <limit command_effort="40" current="10" effort="80" gear_velocity="10" lower="-1.62" upper="1.62" velocity="15" />
      <dynamics damping="0.0" friction="0.0" />
   </joint>
   <!-- Link flex_2 rigth front -->
   <link name="RR_FLX2">
      <visual>
         <origin rpy="0 0 0.0" xyz="0 0 0" />
         <geometry>
            <!-- <mesh filename="package://to_description/meshes/tibia_rigth.stl" scale="0.001 0.001     0.001" /> -->
            <mesh filename="package://to_description/meshes/tibia_rigth.dae" scale="0.001 0.001     0.001" />
         </geometry>
         <!-- <material name="to_material" /> -->
      </visual>
      <collision>
          <!-- Main Body -->
         <origin rpy="0 0 0" xyz="0.0 -0.0305 -0.063" />
         <geometry>
            <box size="0.021 0.021 0.146" />
         </geometry>
      </collision>
      
      <inertial>
         <origin rpy="0 0 0" xyz="-0.0013 0.045121 -0.075788" />
         <mass value="0.263" />
         <inertia ixx="0.001" ixy="-0.000" ixz="0.000" iyy="0.001" iyz="0.000" izz="0.001" />
      </inertial>
   </link>
  <!-- Flex  joint 2  -->
   <joint name="RR_FF2" type="revolute">
      <parent link="RR_FLX1" />
      <child link="RR_FLX2" />
      <origin xyz="0.0 -0.064575 -0.1534" rpy="0.0 0.0 0.0"/>
      <axis xyz="0 1 0" />
      <limit command_effort="40" current="10" effort="80" gear_velocity="10" lower="-1.62" upper="1.62" velocity="15" />
      <dynamics damping="0.0" friction="0.0" />
   </joint>
   <!-- foot -->
   <link name="RR_FT">
      <visual>
         <origin rpy="0 0 0.0" xyz="0 0 0" />
         <geometry>
            <!-- <mesh filename="package://to_description/meshes/foot.stl" scale="0.001 0.001     0.001" /> -->
            <mesh filename="package://to_description/meshes/foot.dae" scale="0.001 0.001     0.001" />
         </geometry>
         <!-- <material name="to_material" /> -->
      </visual>
      <collision>
         <origin xyz="0 0.0 0.0278" />
         <geometry>
            <sphere radius="0.0278" />
         </geometry>
      </collision>
      <inertial>
         <origin rpy="0 0 0" xyz="-0.0013 0.045121 -0.075788" />
         <mass value="0.263" />
         <inertia ixx="0.001" ixy="-0.000" ixz="0.000" iyy="0.001" iyz="0.000" izz="0.001" />
      </inertial>
   </link>
   <!-- fixed -->
   <joint name="RR_FT_FX" type="fixed">
      <parent link="RR_FLX2" />
      <child link="RR_FT" />
      <origin xyz="0.0 -0.0304 -0.192206" rpy="0 0 0"/>
   </joint>
   <!-- <transmission name="LF_HAA_trans">
      <type>transmission_interface/SimpleTransmission</type>
      <joint name="LF_HAA">
         <hardwareInterface>hardware_interface/EffortJointInterface</hardwareInterface>
      </joint>
      <actuator name="LF_HAA_actuator">
         <hardwareInterface>hardware_interface/EffortJointInterface</hardwareInterface>
         <mechanicalReduction>1</mechanicalReduction>
      </actuator>
   </transmission>  -->

</robot>